<?xml version="1.0" encoding="UTF-8"?>
<!-- Generated by org.testng.reporters.JUnitXMLReporter -->
<testsuite ignored="0" hostname="ROHIT-PC" failures="1" tests="2" name="Weekend loan apply by user" time="20.774" errors="0" timestamp="2025-02-27T15:42:28 IST">
  <testcase classname="WeekendLoanTest.ApplyWeekendLoanWithGuarantorTest" name="goToLoanPage" time="0.283"/>
  <testcase classname="WeekendLoanTest.ApplyWeekendLoanWithGuarantorTest" name="applyLoan" time="7.081">
    <failure type="java.lang.Exception" message="catching exception for loan number.">
      <![CDATA[java.lang.Exception: catching exception for loan number.
at WeekendLoan.AddWeekendLoanPage.getLoanNumber(AddWeekendLoanPage.java:169)
at WeekendLoanTest.ApplyWeekendLoanWithGuarantorTest.applyLoan(ApplyWeekendLoanWithGuarantorTest.java:105)
at java.base/java.util.ArrayList.forEach(ArrayList.java:1597)
at com.intellij.rt.testng.IDEARemoteTestNG.run(IDEARemoteTestNG.java:65)
at com.intellij.rt.testng.RemoteTestNGStarter.main(RemoteTestNGStarter.java:105)
... Removed 22 stack frames]]>
    </failure>
  </testcase> <!-- applyLoan -->
</testsuite> <!-- Weekend loan apply by user -->
